<?xml version="1.0" encoding="UTF-8"?><testrun name="Record_Indexer" project="Record_Indexer" tests="3" started="3" failures="0" errors="1" ignored="0">
  <testsuite name="server.ServerUnitTests" time="0.0">
    <testcase name="test_1" classname="server.ServerUnitTests" time="0.0"/>
  </testsuite>
  <testsuite name="server.access.UserDAOTest" time="0.929">
    <testcase name="testGetAll" classname="server.access.UserDAOTest" time="0.929">
      <error>server.DatabaseException: Error finding User
	at server.access.UserDAO.getAll(UserDAO.java:66)
	at server.access.UserDAOTest.setUp(UserDAOTest.java:43)
	at sun.reflect.NativeMethodAccessorImpl.invoke0(Native Method)
	at sun.reflect.NativeMethodAccessorImpl.invoke(NativeMethodAccessorImpl.java:57)
	at sun.reflect.DelegatingMethodAccessorImpl.invoke(DelegatingMethodAccessorImpl.java:43)
	at java.lang.reflect.Method.invoke(Method.java:606)
	at org.junit.runners.model.FrameworkMethod$1.runReflectiveCall(FrameworkMethod.java:44)
	at org.junit.internal.runners.model.ReflectiveCallable.run(ReflectiveCallable.java:15)
	at org.junit.runners.model.FrameworkMethod.invokeExplosively(FrameworkMethod.java:41)
	at org.junit.internal.runners.statements.RunBefores.evaluate(RunBefores.java:27)
	at org.junit.internal.runners.statements.RunAfters.evaluate(RunAfters.java:31)
	at org.junit.runners.BlockJUnit4ClassRunner.runNotIgnored(BlockJUnit4ClassRunner.java:79)
	at org.junit.runners.BlockJUnit4ClassRunner.runChild(BlockJUnit4ClassRunner.java:71)
	at org.junit.runners.BlockJUnit4ClassRunner.runChild(BlockJUnit4ClassRunner.java:49)
	at org.junit.runners.ParentRunner$3.run(ParentRunner.java:193)
	at org.junit.runners.ParentRunner$1.schedule(ParentRunner.java:52)
	at org.junit.runners.ParentRunner.runChildren(ParentRunner.java:191)
	at org.junit.runners.ParentRunner.access$000(ParentRunner.java:42)
	at org.junit.runners.ParentRunner$2.evaluate(ParentRunner.java:184)
	at org.junit.internal.runners.statements.RunBefores.evaluate(RunBefores.java:28)
	at org.junit.internal.runners.statements.RunAfters.evaluate(RunAfters.java:31)
	at org.junit.runners.ParentRunner.run(ParentRunner.java:236)
	at org.eclipse.jdt.internal.junit4.runner.JUnit4TestReference.run(JUnit4TestReference.java:50)
	at org.eclipse.jdt.internal.junit.runner.TestExecution.run(TestExecution.java:38)
	at org.eclipse.jdt.internal.junit.runner.RemoteTestRunner.runTests(RemoteTestRunner.java:467)
	at org.eclipse.jdt.internal.junit.runner.RemoteTestRunner.runTests(RemoteTestRunner.java:683)
	at org.eclipse.jdt.internal.junit.runner.RemoteTestRunner.run(RemoteTestRunner.java:390)
	at org.eclipse.jdt.internal.junit.runner.RemoteTestRunner.main(RemoteTestRunner.java:197)
Caused by: java.sql.SQLException: column 0 out of bounds [1,8]
	at org.sqlite.RS.checkCol(RS.java:71)
	at org.sqlite.RS.markCol(RS.java:78)
	at org.sqlite.RS.getInt(RS.java:289)
	at server.access.UserDAO.getAll(UserDAO.java:58)
	... 27 more

</error>
    </testcase>
  </testsuite>
  <testsuite name="client.ClientUnitTests" time="0.0">
    <testcase name="test_1" classname="client.ClientUnitTests" time="0.0"/>
  </testsuite>
</testrun>
